Workbook

Sheet داشبرد
B1: داشبورد مدیریتی لجستیک مواد
AA2: فاز یک: اظهار تا ترخیص گمرکی | AB2: کل فاز (بدون لحاظ مسیر)
C3: انتخاب فاز: | D3: فاز چهار: کل چرخه لجستیک | AA3: فاز دو: ترخیص تا بارگیری | AB3: آستارا به تهران
B4: ⚙ | C4: انتخاب مسیر: | D4: کل فاز (بدون لحاظ مسیر) | AA4: فاز سه: حمل بین شهری تا انبار مقصد | AB4: بندرعباس به اصفهان
B5: 🛣 | C5: مسیر انتخاب شده: | D5: =D3&" | "&D4 -> فاز چهار: کل چرخه لجستیک | کل فاز (بدون لحاظ مسیر) | AA5: فاز چهار: کل چرخه لجستیک | AB5: بندرعباس به تهران
AB6: بندرعباس به زرندیه
B7: میانگین زمان چرخه (لیدتایم) | C7: نرخ مغایرت وزنی | D7: کارایی فرایند (PCE) | E7: سهم تأخیرات گمرک و بارگیری | F7: تعداد کل سفرها (N) | G7: نرخ تحویل به‌موقع (OTD) | H7: ضریب تغییرات | I7: ضریب چولگی | J7: انحراف معیار | AB7: چابهار به تهران
B8: =INDEX(محاسبات!$H$2:$H$29,MATCH($D$5,محاسبات!$C$2:$C$29,0)) -> 16.878136 | C8: =INDEX(محاسبات!$M$2:$M$29,MATCH($D$5,محاسبات!$C$2:$C$29,0)) -> 7.9059332 | D8: =INDEX(محاسبات!$N$2:$N$29,MATCH($D$5,محاسبات!$C$2:$C$29,0)) -> 27.405745 | E8: =INDEX(محاسبات!$O$2:$O$29,MATCH($D$5,محاسبات!$C$2:$C$29,0)) -> 100 | F8: =INDEX(محاسبات!$D:$D,MATCH($D$5,محاسبات!$C:$C,0)) -> 279 | G8: =INDEX(محاسبات!$P$2:$P$29,MATCH($D$5,محاسبات!$C$2:$C$29,0)) -> 69.892473 | H8: =_xlfn.AGGREGATE(7, 6,'پایگاه داده باکس پلات'!$AD$3:$AD$281) / _xlfn.AGGREGATE(1, 6,'پایگاه داده باکس پلات'!AD3:AD281) -> 1.2709711 | I8: {=SKEW(_xlfn._xlws.FILTER('پایگاه داده باکس پلات'!$AD$3:$AD$281, ISNUMBER('پایگاه داده باکس پلات'!$AD$3:$AD$281)))} -> 5.4624491 | J8: =_xlfn.AGGREGATE(7, 6,'پایگاه داده باکس پلات'!$AD$3:$AD$281) -> 21.451623 | AB8: چابهار به مشهد
B9: واحد: روز | C9: واحد: % | D9: واحد: % | E9: واحد: % | F9: واحد: سفر | G9: واحد: % | H9: واحد: % | I9: واحد: مقیاسی بین +3 و -3 | J9: واحد: روز
B11: 📊 باکس پلات (خلاصه آماره ها) | E11: 🧪 پنل شبیه‌سازی مونت‌کارلو — فاز ۳ و مسیرهای مجاز
B12: آماره | C12: مقدار | E12: زمان تعهد قانونی (SLA) | F12: =IF(AND($D$3="فاز سه: حمل بین شهری تا انبار مقصد",OR($D$4="کل فاز (بدون لحاظ مسیر)",$D$4="بندرعباس به اصفهان",$D$4="بندرعباس به تهران",$D$4="بندرعباس به زرندیه")),INDEX(محاسبات!$W:$W,MATCH($D$5,محاسبات!$C:$C,0)),"-") -> -
B13: حداقل (Min) | C13: =INDEX(محاسبات!$E:$E,MATCH($D$5,محاسبات!$C:$C,0)) -> 3 | E13: میانگین زمان حمل شبیه‌سازی شده | F13: =IF(AND($D$3="فاز سه: حمل بین شهری تا انبار مقصد",OR($D$4="کل فاز (بدون لحاظ مسیر)",$D$4="بندرعباس به اصفهان",$D$4="بندرعباس به تهران",$D$4="بندرعباس به زرندیه")),INDEX(محاسبات!$X:$X,MATCH($D$5,محاسبات!$C:$C,0)),"-") -> -
B14: چارک اول (Q1) | C14: =INDEX(محاسبات!$F:$F,MATCH($D$5,محاسبات!$C:$C,0)) -> 8 | E14: میانگین انحراف معیار شبیه‌سازی شده | F14: =IF(AND($D$3="فاز سه: حمل بین شهری تا انبار مقصد",OR($D$4="کل فاز (بدون لحاظ مسیر)",$D$4="بندرعباس به اصفهان",$D$4="بندرعباس به تهران",$D$4="بندرعباس به زرندیه")),INDEX(محاسبات!$Y:$Y,MATCH($D$5,محاسبات!$C:$C,0)),"-") -> -
B15: میانه (Median) | C15: =INDEX(محاسبات!$G:$G,MATCH($D$5,محاسبات!$C:$C,0)) -> 11 | E15: میانگین نرخ تحویل به‌موقع شبیه‌سازی شده | F15: =IF(AND($D$3="فاز سه: حمل بین شهری تا انبار مقصد",OR($D$4="کل فاز (بدون لحاظ مسیر)",$D$4="بندرعباس به اصفهان",$D$4="بندرعباس به تهران",$D$4="بندرعباس به زرندیه")),INDEX(محاسبات!$Z:$Z,MATCH($D$5,محاسبات!$C:$C,0)),"-") -> -
B16: چارک سوم (Q3) | C16: =INDEX(محاسبات!$I:$I,MATCH($D$5,محاسبات!$C:$C,0)) -> 16 | E16: میانگین ضریب تغییرات | F16: =IF(AND($D$3="فاز سه: حمل بین شهری تا انبار مقصد",OR($D$4="کل فاز (بدون لحاظ مسیر)",$D$4="بندرعباس به اصفهان",$D$4="بندرعباس به تهران",$D$4="بندرعباس به زرندیه")),INDEX(محاسبات!$AA:$AA,MATCH($D$5,محاسبات!$C:$C,0)),"-") -> -
B17: حداکثر (Max) | C17: =INDEX(محاسبات!$J:$J,MATCH($D$5,محاسبات!$C:$C,0)) -> 183 | E17: شاخص بافر زمانی | F17: =IF(AND($D$3="فاز سه: حمل بین شهری تا انبار مقصد",OR($D$4="کل فاز (بدون لحاظ مسیر)",$D$4="بندرعباس به اصفهان",$D$4="بندرعباس به تهران",$D$4="بندرعباس به زرندیه")),INDEX(محاسبات!$AB:$AB,MATCH($D$5,محاسبات!$C:$C,0)),"-") -> -
B18: دامنه میان‌چارکی (IQR) | C18: =INDEX(محاسبات!$K:$K,MATCH($D$5,محاسبات!$C:$C,0)) -> 8 | E18: تارگت تحویل ۵۰٪ | F18: =IF(AND($D$3="فاز سه: حمل بین شهری تا انبار مقصد",OR($D$4="کل فاز (بدون لحاظ مسیر)",$D$4="بندرعباس به اصفهان",$D$4="بندرعباس به تهران",$D$4="بندرعباس به زرندیه")),INDEX(محاسبات!$AC:$AC,MATCH($D$5,محاسبات!$C:$C,0)),"-") -> -
B19: تعداد داده پرت | C19: =INDEX(محاسبات!$L:$L,MATCH($D$5,محاسبات!$C:$C,0)) -> 29 | E19: تارگت ۹۰٪ | F19: =IF(AND($D$3="فاز سه: حمل بین شهری تا انبار مقصد",OR($D$4="کل فاز (بدون لحاظ مسیر)",$D$4="بندرعباس به اصفهان",$D$4="بندرعباس به تهران",$D$4="بندرعباس به زرندیه")),INDEX(محاسبات!$AD:$AD,MATCH($D$5,محاسبات!$C:$C,0)),"-") -> -
E20: تارگت ۹۵٪ | F20: =IF(AND($D$3="فاز سه: حمل بین شهری تا انبار مقصد",OR($D$4="کل فاز (بدون لحاظ مسیر)",$D$4="بندرعباس به اصفهان",$D$4="بندرعباس به تهران",$D$4="بندرعباس به زرندیه")),INDEX(محاسبات!$AE:$AE,MATCH($D$5,محاسبات!$C:$C,0)),"-") -> -
B25: 📉 تحلیل پارتو — سهم تاخیر به تفکیک فاز
B26: فاز زنجیره لجستیک | C26: مجموع زمان (روز) | D26: میانگین زمان در هر محموله (روز) | E26: سهم درصدی | F26: سهم تجمعی
B27: تشریفات و ارزیابی گمرک | C27: 2295 | D27: 8.2258065 | E27: 0.48736462 | F27: 0.48736462
B28: تخصیص و بارگیری ناوگان | C28: 1600 | D28: 5.734767 | E28: 0.3397749 | F28: 0.82713952
B29: حمل و ترانزیت جاده‌ای | C29: 814 | D29: 2.9175627 | E29: 0.17286048 | F29: 1

Sheet محاسبات
A1: Route_Key | B1: Phase_Key | C1: Combination_Key | D1: N | E1: حداقل (Min) | F1: چارک اول (Q1) | G1: میانه (Median) | H1: میانگین (Mean) | I1: چارک سوم (Q3) | J1: حداکثر (Max) | K1: دامنه میان‌چارکی (IQR) | L1: تعداد داده پرت | M1: درصد مغایرت وزنی | N1: راندمان زمانی فرایند (PCE) | O1: میانگین تاخیر | P1: درصد تحویل به موقع(OTD) | Q1: تعداد تاخیر | R1: Pareto_Route | S1: Pareto_Phase | T1: مجموع روز ها | U1: درصد تاخیر | V1: درصد تاخیر تجمعی | W1: شبیه سازی زمان تعهد قانونی (SLA) | X1: شبیه سازی میانگین زمان | Y1: شبیه سازی انحراف معبار | Z1: شبیه سازی نرخ تحویل به موقع | AA1: شبیه سازی ضریب تغییرات | AB1: شاخص بافر زمانی | AC1: تارگت تحویل 50% (P50) | AD1: تارگت تحویل 90% (P90) | AE1: تارگت تحویل 95% (P95)
A2: کل فاز (بدون لحاظ مسیر) | B2: فاز یک: اظهار تا ترخیص گمرکی | C2: فاز یک: اظهار تا ترخیص گمرکی | کل فاز (بدون لحاظ مسیر) | D2: 279 | E2: 1 | F2: 3 | G2: 5 | H2: 8.2258065 | I2: 10 | J2: 65 | K2: 7 | L2: 20 | M2: 7.9059332 | N2: 27.405745 | O2: 48.74 | P2: 69.892473 | Q2: 84 | R2: بندرعباس به تهران | S2: فاز یک: اظهار تا ترخیص گمرکی | T2: 468 | U2: 0.3326226 | V2: 0.3326226 | W2: - | X2: - | Y2: - | Z2: - | AA2: - | AB2: - | AC2: - | AD2: - | AE2: -
A3: آستارا به تهران | B3: فاز یک: اظهار تا ترخیص گمرکی | C3: فاز یک: اظهار تا ترخیص گمرکی | آستارا به تهران | D3: 10 | E3: 14 | F3: 14 | G3: 38 | H3: 36.5 | I3: 58.25 | J3: 65 | K3: 44.25 | L3: 0 | M3: 8.146902 | N3: 7.3511686 | O3: 2.47 | P3: 80 | Q3: 2 | R3: آستارا به تهران | S3: فاز یک: اظهار تا ترخیص گمرکی | T3: 365 | U3: 0.2594172 | V3: 0.5920398 | W3: - | X3: - | Y3: - | Z3: - | AA3: - | AB3: - | AC3: - | AD3: - | AE3: -
A4: بندرعباس به اصفهان | B4: فاز یک: اظهار تا ترخیص گمرکی | C4: فاز یک: اظهار تا ترخیص گمرکی | بندرعباس به اصفهان | D4: 37 | E4: 2 | F4: 3 | G4: 6 | H4: 6.5675676 | I4: 8 | J4: 15 | K4: 5 | L4: 0 | M4: 7.7890356 | N4: 24.731144 | O4: 4.94 | P4: 89.189189 | Q4: 4 | R4: بندرعباس به اصفهان | S4: فاز یک: اظهار تا ترخیص گمرکی | T4: 243 | U4: 0.17270789 | V4: 0.76474769 | W4: - | X4: - | Y4: - | Z4: - | AA4: - | AB4: - | AC4: - | AD4: - | AE4: -
A5: بندرعباس به تهران | B5: فاز یک: اظهار تا ترخیص گمرکی | C5: فاز یک: اظهار تا ترخیص گمرکی | بندرعباس به تهران | D5: 103 | E5: 1 | F5: 2.5 | G5: 4 | H5: 4.5436893 | I5: 5 | J5: 16 | K5: 2.5 | L5: 10 | M5: 8.1155295 | N5: 34.111716 | O5: 29.63 | P5: 76.699029 | Q5: 24 | R5: بندرعباس به زرندیه | S5: فاز یک: اظهار تا ترخیص گمرکی | T5: 194 | U5: 0.13788202 | V5: 0.90262971 | W5: - | X5: - | Y5: - | Z5: - | AA5: - | AB5: - | AC5: - | AD5: - | AE5: -
A6: بندرعباس به زرندیه | B6: فاز یک: اظهار تا ترخیص گمرکی | C6: فاز یک: اظهار تا ترخیص گمرکی | بندرعباس به زرندیه | D6: 32 | E6: 3 | F6: 5 | G6: 5 | H6: 6.0625 | I6: 6.25 | J6: 10 | K6: 1.25 | L6: 11 | M6: 7.7012445 | N6: 25.611515 | O6: 19.75 | P6: 50 | Q6: 16 | R6: چابهار به تهران | S6: فاز یک: اظهار تا ترخیص گمرکی | T6: 80 | U6: 0.056858564 | V6: 0.95948827 | W6: - | X6: - | Y6: - | Z6: - | AA6: - | AB6: - | AC6: - | AD6: - | AE6: -
A7: چابهار به تهران | B7: فاز یک: اظهار تا ترخیص گمرکی | C7: فاز یک: اظهار تا ترخیص گمرکی | چابهار به تهران | D7: 11 | E7: 3 | F7: 5 | G7: 7 | H7: 7.2727273 | I7: 9.5 | J7: 12 | K7: 4.5 | L7: 0 | M7: 7.4802918 | N7: 27.846924 | O7: 6.17 | P7: 54.545455 | Q7: 5 | R7: چابهار به مشهد | S7: فاز یک: اظهار تا ترخیص گمرکی | T7: 57 | U7: 0.040511727 | V7: 1 | W7: - | X7: - | Y7: - | Z7: - | AA7: - | AB7: - | AC7: - | AD7: - | AE7: -
A8: چابهار به مشهد | B8: فاز یک: اظهار تا ترخیص گمرکی | C8: فاز یک: اظهار تا ترخیص گمرکی | چابهار به مشهد | D8: 11 | E8: 2 | F8: 2.5 | G8: 3 | H8: 5.1818182 | I8: 7.5 | J8: 12 | K8: 5 | L8: 0 | M8: 8.2353127 | N8: 27.701587 | O8: 2.47 | P8: 81.818182 | Q8: 2 | R8: آستارا به تهران | S8: فاز یک: اظهار تا ترخیص گمرکی | T8: 437 | U8: 0.46341463 | V8: 0.46341463 | W8: - | X8: - | Y8: - | Z8: - | AA8: - | AB8: - | AC8: - | AD8: - | AE8: -
A9: کل فاز (بدون لحاظ مسیر) | B9: فاز دو: ترخیص تا بارگیری | C9: فاز دو: ترخیص تا بارگیری | کل فاز (بدون لحاظ مسیر) | D9: 279 | E9: 0 | F9: 1 | G9: 2 | H9: 5.734767 | I9: 4 | J9: 143 | K9: 3 | L9: 34 | M9: 7.9059332 | N9: 27.405745 | O9: 33.98 | P9: 69.892473 | Q9: 84 | R9: بندرعباس به تهران | S9: فاز دو: ترخیص تا بارگیری | T9: 257 | U9: 0.27253446 | V9: 0.7359491 | W9: - | X9: - | Y9: - | Z9: - | AA9: - | AB9: - | AC9: - | AD9: - | AE9: -
A10: آستارا به تهران | B10: فاز دو: ترخیص تا بارگیری | C10: فاز دو: ترخیص تا بارگیری | آستارا به تهران | D10: 10 | E10: 0 | F10: 0.5 | G10: 2 | H10: 43.7 | I10: 107.75 | J10: 143 | K10: 107.25 | L10: 0 | M10: 8.146902 | N10: 7.3511686 | O10: 2.47 | P10: 80 | Q10: 2 | R10: بندرعباس به اصفهان | S10: فاز دو: ترخیص تا بارگیری | T10: 99 | U10: 0.10498409 | V10: 0.84093319 | W10: - | X10: - | Y10: - | Z10: - | AA10: - | AB10: - | AC10: - | AD10: - | AE10: -
A11: بندرعباس به اصفهان | B11: فاز دو: ترخیص تا بارگیری | C11: فاز دو: ترخیص تا بارگیری | بندرعباس به اصفهان | D11: 37 | E11: 0 | F11: 1 | G11: 1 | H11: 2.6756757 | I11: 3 | J11: 9 | K11: 2 | L11: 7 | M11: 7.7890356 | N11: 24.731144 | O11: 4.94 | P11: 89.189189 | Q11: 4 | R11: بندرعباس به زرندیه | S11: فاز دو: ترخیص تا بارگیری | T11: 62 | U11: 0.065747614 | V11: 0.90668081 | W11: - | X11: - | Y11: - | Z11: - | AA11: - | AB11: - | AC11: - | AD11: - | AE11: -
A12: بندرعباس به تهران | B12: فاز دو: ترخیص تا بارگیری | C12: فاز دو: ترخیص تا بارگیری | بندرعباس به تهران | D12: 103 | E12: 0 | F12: 1 | G12: 2 | H12: 2.4951456 | I12: 3 | J12: 12 | K12: 2 | L12: 12 | M12: 8.1155295 | N12: 34.111716 | O12: 29.63 | P12: 76.699029 | Q12: 24 | R12: چابهار به مشهد | S12: فاز دو: ترخیص تا بارگیری | T12: 61 | U12: 0.064687169 | V12: 0.97136797 | W12: - | X12: - | Y12: - | Z12: - | AA12: - | AB12: - | AC12: - | AD12: - | AE12: -
A13: بندرعباس به زرندیه | B13: فاز دو: ترخیص تا بارگیری | C13: فاز دو: ترخیص تا بارگیری | بندرعباس به زرندیه | D13: 32 | E13: 0 | F13: 0 | G13: 2 | H13: 1.9375 | I13: 3.25 | J13: 5 | K13: 3.25 | L13: 0 | M13: 7.7012445 | N13: 25.611515 | O13: 19.75 | P13: 50 | Q13: 16 | R13: چابهار به تهران | S13: فاز دو: ترخیص تا بارگیری | T13: 27 | U13: 0.028632025 | V13: 1 | W13: - | X13: - | Y13: - | Z13: - | AA13: - | AB13: - | AC13: - | AD13: - | AE13: -
... A17: آستارا به تهران | B17: فاز سه: حمل بین شهری تا انبار مقصد | C17: فاز سه: حمل بین شهری تا انبار مقصد | آستارا به تهران | D17: 10 | E17: 1 | F17: 2 | G17: 2 | H17: 2.3 | I17: 2 | J17: 5 | K17: 0 | L17: 3 | M17: 8.146902 | N17: 7.3511686 | O17: 2.47 | P17: 80 | Q17: 2 | R17: چابهار به مشهد | S17: فاز سه: حمل بین شهری تا انبار مقصد | T17: 44 | U17: 0.075085324 | V17: 0.89931741 | W17: - | X17: - | Y17: - | Z17: - | AA17: - | AB17: - | AC17: - | AD17: - | AE17: -
A18: بندرعباس به اصفهان | B18: فاز سه: حمل بین شهری تا انبار مقصد | C18: فاز سه: حمل بین شهری تا انبار مقصد | بندرعباس به اصفهان | D18: 37 | E18: 1 | F18: 2 | G18: 2 | H18: 2.4864865 | I18: 3 | J18: 5 | K18: 1 | L18: 1 | M18: 7.7890356 | N18: 24.731144 | O18: 4.94 | P18: 89.189189 | Q18: 4 | R18: چابهار به تهران | S18: فاز سه: حمل بین شهری تا انبار مقصد | T18: 36 | U18: 0.061433447 | V18: 0.96075085 | W18: 3 | X18: ='شبیه سازی مسیر بندر به اصفهان'!G4 -> 3.172809 | Y18: ='شبیه سازی مسیر بندر به اصفهان'!G5 -> 0.61840019 | Z18: ='شبیه سازی مسیر بندر به اصفهان'!G6 -> 0.46 | AA18: ='شبیه سازی مسیر بندر به اصفهان'!G7 -> 0.19490622 | AB18: ='شبیه سازی مسیر بندر به اصفهان'!G11 -> 0.52731027 | AC18: =PERCENTILE('شبیه سازی مسیر بندر به اصفهان'!$M$4:$M$1003,0.5) -> 3.0543688 | AD18: =PERCENTILE('شبیه سازی مسیر بندر به اصفهان'!$M$4:$M$1003,0.9) -> 4.0316876 | AE18: =PERCENTILE('شبیه سازی مسیر بندر به اصفهان'!$M$4:$M$1003,0.95) -> 4.5819308
A19: بندرعباس به تهران | B19: فاز سه: حمل بین شهری تا انبار مقصد | C19: فاز سه: حمل بین شهری تا انبار مقصد | بندرعباس به تهران | D19: 103 | E19: 1 | F19: 2 | G19: 3 | H19: 3 | I19: 3 | J19: 5 | K19: 1 | L19: 8 | M19: 8.1155295 | N19: 34.111716 | O19: 29.63 | P19: 76.699029 | Q19: 24 | R19: آستارا به تهران | S19: فاز سه: حمل بین شهری تا انبار مقصد | T19: 23 | U19: 0.039249147 | V19: 1 | W19: 3 | X19: ='شبیه سازی مسیر بندر به تهران'!G4 -> 3.5301157 | Y19: ='شبیه سازی مسیر بندر به تهران'!G5 -> 0.85842617 | Z19: ='شبیه سازی مسیر بندر به تهران'!G6 -> 0.332 | AA19: ='شبیه سازی مسیر بندر به تهران'!G7 -> 0.24317225 | AB19: ='شبیه سازی مسیر بندر به تهران'!G11 -> 0.71872566 | AC19: =PERCENTILE('شبیه سازی مسیر بندر به تهران'!$M$4:$M$1003,0.5) -> 3.3722418 | AD19: =PERCENTILE('شبیه سازی مسیر بندر به تهران'!$M$4:$M$1003,0.9) -> 4.7945444 | AE19: =PERCENTILE('شبیه سازی مسیر بندر به تهران'!$M$4:$M$1003,0.95) -> 5.156177
A20: بندرعباس به زرندیه | B20: فاز سه: حمل بین شهری تا انبار مقصد | C20: فاز سه: حمل بین شهری تا انبار مقصد | بندرعباس به زرندیه | D20: 32 | E20: 2 | F20: 2 | G20: 2.5 | H20: 2.5625 | I20: 3 | J20: 4 | K20: 1 | L20: 0 | M20: 7.7012445 | N20: 25.611515 | O20: 19.75 | P20: 50 | Q20: 16 | R20: بندرعباس به تهران | S20: فاز سه: حمل بین شهری تا انبار مقصد | T20: 1034 | U20: 0.35217984 | V20: 0.35217984 | W20: 2 | X20: ='شبیه سازی مسیر بندر به زرندیه'!G4 -> 2.7354483 | Y20: ='شبیه سازی مسیر بندر به زرندیه'!G5 -> 0.85039403 | Z20: ='شبیه سازی مسیر بندر به زرندیه'!G6 -> 0.259 | AA20: ='شبیه سازی مسیر بندر به زرندیه'!G7 -> 0.31087922 | AB20: ='شبیه سازی مسیر بندر به زرندیه'!G11 -> 1.0413465 | AC20: =PERCENTILE('شبیه سازی مسیر بندر به زرندیه'!$M$4:$M$1003,0.5) -> 2.6455873 | AD20: =PERCENTILE('شبیه سازی مسیر بندر به زرندیه'!$M$4:$M$1003,0.9) -> 3.8715566 | AE20: =PERCENTILE('شبیه سازی مسیر بندر به زرندیه'!$M$4:$M$1003,0.95) -> 4.0826931
A21: چابهار به تهران | B21: فاز سه: حمل بین شهری تا انبار مقصد | C21: فاز سه: حمل بین شهری تا انبار مقصد | چابهار به تهران | D21: 11 | E21: 2 | F21: 2.5 | G21: 3 | H21: 3.2727273 | I21: 4 | J21: 5 | K21: 1.5 | L21: 0 | M21: 7.4802918 | N21: 27.846924 | O21: 6.17 | P21: 54.545455 | Q21: 5 | R21: آستارا به تهران | S21: فاز سه: حمل بین شهری تا انبار مقصد | T21: 825 | U21: 0.28099455 | V21: 0.63317439 | W21: - | X21: - | Y21: - | Z21: - | AA21: - | AB21: - | AC21: - | AD21: - | AE21: -
A22: چابهار به مشهد | B22: فاز سه: حمل بین شهری تا انبار مقصد | C22: فاز سه: حمل بین شهری تا انبار مقصد | چابهار به مشهد | D22: 11 | E22: 3 | F22: 4 | G22: 4 | H22: 4 | I22: 4 | J22: 5 | K22: 0 | L22: 4 | M22: 8.2353127 | N22: 27.701587 | O22: 2.47 | P22: 81.818182 | Q22: 2 | R22: بندرعباس به اصفهان | S22: فاز سه: حمل بین شهری تا انبار مقصد | T22: 434 | U22: 0.14782016 | V22: 0.78099455 | W22: - | X22: - | Y22: - | Z22: - | AA22: - | AB22: - | AC22: - | AD22: - | AE22: -
A23: کل فاز (بدون لحاظ مسیر) | B23: فاز چهار: کل چرخه لجستیک | C23: فاز چهار: کل چرخه لجستیک | کل فاز (بدون لحاظ مسیر) | D23: 279 | E23: 3 | F23: 8 | G23: 11 | H23: 16.878136 | I23: 16 | J23: 183 | K23: 8 | L23: 29 | M23: 7.9059332 | N23: 27.405745 | O23: 100 | P23: 69.892473 | Q23: 84 | R23: بندرعباس به زرندیه | S23: فاز چهار: کل چرخه لجستیک | T23: 338 | U23: 0.11512262 | V23: 0.89611717 | W23: - | X23: - | Y23: - | Z23: - | AA23: - | AB23: - | AC23: - | AD23: - | AE23: -
A24: آستارا به تهران | B24: فاز چهار: کل چرخه لجستیک | C24: فاز چهار: کل چرخه لجستیک | آستارا به تهران | D24: 10 | E24: 18 | F24: 19.5 | G24: 67 | H24: 82.5 | I24: 153.25 | J24: 183 | K24: 133.75 | L24: 0 | M24: 8.146902 | N24: 7.3511686 | O24: 2.47 | P24: 80 | Q24: 2 | R24: چابهار به مشهد | S24: فاز چهار: کل چرخه لجستیک | T24: 162 | U24: 0.055177112 | V24: 0.95129428 | W24: - | X24: - | Y24: - | Z24: - | AA24: - | AB24: - | AC24: - | AD24: - | AE24: -
A25: بندرعباس به اصفهان | B25: فاز چهار: کل چرخه لجستیک | C25: فاز چهار: کل چرخه لجستیک | بندرعباس به اصفهان | D25: 37 | E25: 6 | F25: 8 | G25: 10 | H25: 11.72973 | I25: 12 | J25: 26 | K25: 4 | L25: 7 | M25: 7.7890356 | N25: 24.731144 | O25: 4.94 | P25: 89.189189 | Q25: 4 | R25: چابهار به تهران | S25: فاز چهار: کل چرخه لجستیک | T25: 143 | U25: 0.048705722 | V25: 1 | W25: - | X25: - | Y25: - | Z25: - | AA25: - | AB25: - | AC25: - | AD25: - | AE25: -
A26: بندرعباس به تهران | B26: فاز چهار: کل چرخه لجستیک | C26: فاز چهار: کل چرخه لجستیک | بندرعباس به تهران | D26: 103 | E26: 3 | F26: 7 | G26: 9 | H26: 10.038835 | I26: 12.5 | J26: 23 | K26: 5.5 | L26: 2 | M26: 8.1155295 | N26: 34.111716 | O26: 29.63 | P26: 76.699029 | Q26: 24 | S26: فاز چهار: کل چرخه لجستیک | W26: - | X26: - | Y26: - | Z26: - | AA26: - | AB26: - | AC26: - | AD26: - | AE26: -
A27: بندرعباس به زرندیه | B27: فاز چهار: کل چرخه لجستیک | C27: فاز چهار: کل چرخه لجستیک | بندرعباس به زرندیه | D27: 32 | E27: 5 | F27: 9 | G27: 11 | H27: 10.5625 | I27: 12 | J27: 14 | K27: 3 | L27: 0 | M27: 7.7012445 | N27: 25.611515 | O27: 19.75 | P27: 50 | Q27: 16 | S27: فاز چهار: کل چرخه لجستیک | W27: - | X27: - | Y27: - | Z27: - | AA27: - | AB27: - | AC27: - | AD27: - | AE27: -
A28: چابهار به تهران | B28: فاز چهار: کل چرخه لجستیک | C28: فاز چهار: کل چرخه لجستیک | چابهار به تهران | D28: 11 | E28: 6 | F28: 9.5 | G28: 14 | H28: 13 | I28: 16.5 | J28: 20 | K28: 7 | L28: 0 | M28: 7.4802918 | N28: 27.846924 | O28: 6.17 | P28: 54.545455 | Q28: 5 | S28: فاز چهار: کل چرخه لجستیک | W28: - | X28: - | Y28: - | Z28: - | AA28: - | AB28: - | AC28: - | AD28: - | AE28: -
A29: چابهار به مشهد | B29: فاز چهار: کل چرخه لجستیک | C29: فاز چهار: کل چرخه لجستیک | چابهار به مشهد | D29: 11 | E29: 11 | F29: 12 | G29: 16 | H29: 14.727273 | I29: 17.5 | J29: 19 | K29: 5.5 | L29: 0 | M29: 8.2353127 | N29: 27.701587 | O29: 2.47 | P29: 81.818182 | Q29: 2 | S29: فاز چهار: کل چرخه لجستیک | W29: - | X29: - | Y29: - | Z29: - | AA29: - | AB29: - | AC29: - | AD29: - | AE29: -

Sheet پایگاه داده
A1: شماره کالا | B1: نام شهر گمرک | C1: مقصد بارگیری | D1: شماره کوتاژ | E1: نوع کالا | F1: زمان اظهار تا ترخیص | G1: زمان ترخیص تا بارگیری | H1: زمان حمل بین شهری | I1: زمان استاندارد مسیر | J1: زمان خوشبینانه | K1: زمان بدبینانه | L1: انحراف زمانی (روز) | M1: تحویل به موقع(OTD) | N1: کل زمان چرخه لجستیک | O1: وزن بارنامه مبدا | P1: وزن باسکول انبار مقصد | Q1: کسری وزن | R1: وزن واحد کیسه | S1: تعداد کیسه ارسالی | T1: تعداد کیسه معیوب | U1: درصد مغایرت وزنی | V1: راندمان زمانی فرایند)(PCE)
A2: 1 | B2: بندر عباس | C2: اصفهان | D2: 37140476 | E2: قهوه دانه سبز | F2: 7 | G2: 0 | H2: 3 | I2: 3 | J2: 2 | K2: 4 | L2: 0 | M2: 1 | N2: 10 | O2: 24.75 | P2: 23.139 | Q2: 1.611 | R2: 60 | S2: 412 | T2: 26 | U2: 6.5090909 | V2: 30
A3: 2 | B3: بندر عباس | C3: اصفهان | D3: 37140476 | E3: قهوه دانه سبز | F3: 7 | G3: 0 | H3: 3 | I3: 3 | J3: 2 | K3: 4 | L3: 0 | M3: 1 | N3: 10 | O3: 24.75 | P3: 22.622 | Q3: 2.128 | R3: 60 | S3: 412 | T3: 35 | U3: 8.5979798 | V3: 30
A4: 3 | B4: بندر عباس | C4: اصفهان | D4: 37140476 | E4: قهوه دانه سبز | F4: 7 | G4: 0 | H4: 2 | I4: 3 | J4: 2 | K4: 4 | L4: -1 | M4: 1 | N4: 9 | O4: 24.75 | P4: 22.81 | Q4: 1.94 | R4: 60 | S4: 412 | T4: 32 | U4: 7.8383838 | V4: 22.222222
A5: 4 | B5: بندر عباس | C5: تهران | D5: 37140476 | E5: قهوه دانه سبز | F5: 7 | G5: 0 | H5: 5 | I5: 3 | J5: 2 | K5: 5 | L5: 2 | M5: 0 | N5: 12 | O5: 23.036 | P5: 21.718 | Q5: 1.318 | R5: 60 | S5: 383 | T5: 21 | U5: 5.7214794 | V5: 41.666667
A6: 5 | B6: بندر عباس | C6: اصفهان | D6: 37140476 | E6: قهوه دانه سبز | F6: 7 | G6: 0 | H6: 2 | I6: 3 | J6: 2 | K6: 4 | L6: -1 | M6: 1 | N6: 9 | O6: 21.93 | P6: 20.726 | Q6: 1.204 | R6: 60 | S6: 365 | T6: 20 | U6: 5.4901961 | V6: 22.222222
A7: 6 | B7: بندر عباس | C7: اصفهان | D7: 37140476 | E7: قهوه دانه سبز | F7: 7 | G7: 0 | H7: 3 | I7: 3 | J7: 2 | K7: 4 | L7: 0 | M7: 1 | N7: 10 | O7: 21.586 | P7: 19.423 | Q7: 2.163 | R7: 60 | S7: 359 | T7: 36 | U7: 10.020384 | V7: 30
A8: 7 | B8: بندر عباس | C8: تهران | D8: 37140476 | E8: قهوه دانه سبز | F8: 7 | G8: 0 | H8: 2 | I8: 3 | J8: 2 | K8: 5 | L8: -1 | M8: 1 | N8: 9 | O8: 24.75 | P8: 22.245 | Q8: 2.505 | R8: 60 | S8: 412 | T8: 41 | U8: 10.121212 | V8: 22.222222
A9: 8 | B9: آستارا | C9: قزوین | D9: 37144586 | E9: عدس درشت روس | F9: 38 | G9: 0 | H9: 2 | I9: 1 | J9: 1 | K9: 2 | L9: 1 | M9: 0 | N9: 40 | O9: 24.75 | P9: 23.107 | Q9: 1.643 | R9: 25 | S9: 990 | T9: 65 | U9: 6.6383838 | V9: 5
A10: 9 | B10: آستارا | C10: قزوین | D10: 37144586 | E10: عدس درشت روس | F10: 38 | G10: 0 | H10: 2 | I10: 1 | J10: 1 | K10: 2 | L10: 1 | M10: 0 | N10: 40 | O10: 24.745 | P10: 22.802 | Q10: 1.943 | R10: 25 | S10: 989 | T10: 77 | U10: 7.8520913 | V10: 5
A11: 10 | B11: آستارا | C11: قزوین | D11: 37144586 | E11: عدس درشت روس | F11: 38 | G11: 0 | H11: 1 | I11: 1 | J11: 1 | K11: 2 | L11: 0 | M11: 1 | N11: 39 | O11: 24.75 | P11: 22.446 | Q11: 2.304 | R11: 25 | S11: 990 | T11: 92 | U11: 9.3090909 | V11: 2.5641026
A12: 11 | B12: آستارا | C12: قزوین | D12: 37144586 | E12: عدس درشت روس | F12: 38 | G12: 0 | H12: 2 | I12: 1 | J12: 1 | K12: 2 | L12: 1 | M12: 0 | N12: 40 | O12: 20.663 | P12: 18.607 | Q12: 2.056 | R12: 25 | S12: 826 | T12: 82 | U12: 9.9501524 | V12: 5
A13: 12 | B13: آستارا | C13: تهران | D13: 37822411 | E13: عدس درشت روس | F13: 38 | G13: 143 | H13: 2 | I13: 2 | J13: 1 | K13: 2 | L13: 0 | M13: 1 | N13: 183 | O13: 24.75 | P13: 22.456 | Q13: 2.294 | R13: 25 | S13: 990 | T13: 91 | U13: 9.2686869 | V13: 1.0928962
... A33: 32 | B33: بندر عباس | C33: اصفهان | D33: 37234942 | E33: قهوه دانه سبز | F33: 3 | G33: 2 | H33: 2 | I33: 3 | J33: 2 | K33: 4 | L33: -1 | M33: 1 | N33: 7 | O33: 24.75 | P33: 23.124 | Q33: 1.626 | R33: 60 | S33: 412 | T33: 27 | U33: 6.569697 | V33: 28.571429
A34: 33 | B34: بندر عباس | C34: اصفهان | D34: 37211755-37234942 | E34: قهوه دانه سبز | F34: 3 | G34: 3 | H34: 3 | I34: 3 | J34: 2 | K34: 4 | L34: 0 | M34: 1 | N34: 9 | O34: 24.75 | P34: 23.193 | Q34: 1.557 | R34: 60 | S34: 412 | T34: 25 | U34: 6.2909091 | V34: 33.333333
A35: 34 | B35: بندر عباس | C35: اصفهان | D35: 37211755 | E35: قهوه دانه سبز | F35: 3 | G35: 3 | H35: 3 | I35: 3 | J35: 2 | K35: 4 | L35: 0 | M35: 1 | N35: 9 | O35: 24.68 | P35: 22.06 | Q35: 2.62 | R35: 60 | S35: 411 | T35: 43 | U35: 10.615883 | V35: 33.333333
A36: 35 | B36: بندر عباس | C36: اصفهان | D36: 37211755 | E36: قهوه دانه سبز | F36: 3 | G36: 3 | H36: 4 | I36: 3 | J36: 2 | K36: 4 | L36: 1 | M36: 0 | N36: 10 | O36: 23.02 | P36: 22.656 | Q36: 0.364 | R36: 60 | S36: 383 | T36: 6 | U36: 1.5812337 | V36: 40
A37: 36 | B37: بندر عباس | C37: اصفهان | D37: 37331755 | E37: قهوه دانه سبز | F37: 8 | G37: 1 | H37: 2 | I37: 3 | J37: 2 | K37: 4 | L37: -1 | M37: 1 | N37: 11 | O37: 22.893 | P37: 21.336 | Q37: 1.557 | R37: 60 | S37: 381 | T37: 25 | U37: 6.8012056 | V37: 18.181818
A38: 37 | B38: بندر عباس | C38: اصفهان | D38: 37331755 | E38: قهوه دانه سبز | F38: 8 | G38: 1 | H38: 3 | I38: 3 | J38: 2 | K38: 4 | L38: 0 | M38: 1 | N38: 12 | O38: 21.855 | P38: 20.46 | Q38: 1.395 | R38: 60 | S38: 364 | T38: 23 | U38: 6.3829787 | V38: 25
A39: 38 | B39: بندر عباس | C39: اصفهان | D39: 37331755 | E39: قهوه دانه سبز | F39: 8 | G39: 1 | H39: 3 | I39: 3 | J39: 2 | K39: 4 | L39: 0 | M39: 1 | N39: 12 | O39: 22.48 | P39: 19.739 | Q39: 2.741 | R39: 60 | S39: 374 | T39: 45 | U39: 12.19306 | V39: 25
A40: 39 | B40: بندر عباس | C40: تهران | D40: 37382126 | E40: پودر نارگیل | F40: 4 | G40: 2 | H40: 3 | I40: 3 | J40: 2 | K40: 5 | L40: 0 | M40: 1 | N40: 9 | O40: 24.75 | P40: 21.852 | Q40: 2.898 | R40: 60 | S40: 412 | T40: 48 | U40: 11.709091 | V40: 33.333333
A41: 40 | B41: بندر عباس | C41: تهران | D41: 37382126 | E41: پودر نارگیل | F41: 4 | G41: 2 | H41: 3 | I41: 3 | J41: 2 | K41: 5 | L41: 0 | M41: 1 | N41: 9 | O41: 24.75 | P41: 22.644 | Q41: 2.106 | R41: 60 | S41: 412 | T41: 35 | U41: 8.5090909 | V41: 33.333333
A42: 41 | B42: بندر عباس | C42: تهران | D42: 37382126 | E42: پودر نارگیل | F42: 4 | G42: 2 | H42: 3 | I42: 3 | J42: 2 | K42: 5 | L42: 0 | M42: 1 | N42: 9 | O42: 24.75 | P42: 22.332 | Q42: 2.418 | R42: 60 | S42: 412 | T42: 40 | U42: 9.769697 | V42: 33.333333
A43: 42 | B43: بندر عباس | C43: تهران | D43: 37385059 | E43: تخمه آفتابگردان | F43: 4 | G43: 1 | H43: 3 | I43: 3 | J43: 2 | K43: 5 | L43: 0 | M43: 1 | N43: 8 | O43: 24.75 | P43: 22.107 | Q43: 2.643 | R43: 60 | S43: 412 | T43: 44 | U43: 10.678788 | V43: 37.5
A44: 43 | B44: بندر عباس | C44: تهران | D44: 37385059 | E44: تخمه آفتابگردان | F44: 4 | G44: 1 | H44: 3 | I44: 3 | J44: 2 | K44: 5 | L44: 0 | M44: 1 | N44: 8 | O44: 23.058 | P44: 19.984 | Q44: 3.074 | R44: 25 | S44: 922 | T44: 122 | U44: 13.331599 | V44: 37.5
A45: 44 | B45: بندر عباس | C45: تهران | D45: 37385059 | E45: تخمه آفتابگردان | F45: 4 | G45: 1 | H45: 3 | I45: 3 | J45: 2 | K45: 5 | L45: 0 | M45: 1 | N45: 8 | O45: 24.75 | P45: 22.381 | Q45: 2.369 | R45: 25 | S45: 990 | T45: 94 | U45: 9.5717172 | V45: 37.5
A46: 45 | B46: بندر عباس | C46: تهران | D46: 37385059 | E46: تخمه آفتابگردان | F46: 4 | G46: 1 | H46: 3 | I46: 3 | J46: 2 | K46: 5 | L46: 0 | M46: 1 | N46: 8 | O46: 22.751 | P46: 20.676 | Q46: 2.075 | R46: 25 | S46: 910 | T46: 83 | U46: 9.1204782 | V46: 37.5
... A82: 81 | B82: بندر عباس | C82: اصفهان | D82: 37676068 | E82: قهوه دانه سبز | F82: 15 | G82: 8 | H82: 2 | I82: 3 | J82: 2 | K82: 4 | L82: -1 | M82: 1 | N82: 25 | O82: 24.75 | P82: 23.201 | Q82: 1.549 | R82: 60 | S82: 412 | T82: 25 | U82: 6.2585859 | V82: 8
A83: 82 | B83: بندر عباس | C83: اصفهان | D83: 37676068و37674292 | E83: قهوه دانه سبز | F83: 15 | G83: 8 | H83: 2 | I83: 3 | J83: 2 | K83: 4 | L83: -1 | M83: 1 | N83: 25 | O83: 24.75 | P83: 23.213 | Q83: 1.537 | R83: 60 | S83: 412 | T83: 25 | U83: 6.210101 | V83: 8
A84: 83 | B84: بندر عباس | C84: تهران | D84: 37655428 | E84: تخمه آفتابگردان | F84: 9 | G84: 4 | H84: 3 | I84: 3 | J84: 2 | K84: 5 | L84: 0 | M84: 1 | N84: 16 | O84: 21.326 | P84: 19.505 | Q84: 1.821 | R84: 60 | S84: 355 | T84: 30 | U84: 8.5388727 | V84: 18.75
A85: 84 | B85: بندر عباس | C85: تهران | D85: 37655428 | E85: تخمه آفتابگردان | F85: 9 | G85: 4 | H85: 3 | I85: 3 | J85: 2 | K85: 5 | L85: 0 | M85: 1 | N85: 16 | O85: 24.75 | P85: 23.475 | Q85: 1.275 | R85: 60 | S85: 412 | T85: 21 | U85: 5.1515152 | V85: 18.75
A86: 85 | B86: بندر عباس | C86: تهران | D86: 37671844 | E86: پودر نارگیل | F86: 1 | G86: 0 | H86: 2 | I86: 3 | J86: 2 | K86: 5 | L86: -1 | M86: 1 | N86: 3 | O86: 21.407 | P86: 19.857 | Q86: 1.55 | R86: 60 | S86: 356 | T86: 25 | U86: 7.2406222 | V86: 66.666667
A87: 86 | B87: بندر عباس | C87: تهران | D87: 37671844 | E87: پودر نارگیل | F87: 1 | G87: 0 | H87: 2 | I87: 3 | J87: 2 | K87: 5 | L87: -1 | M87: 1 | N87: 3 | O87: 24.75 | P87: 23.082 | Q87: 1.668 | R87: 60 | S87: 412 | T87: 27 | U87: 6.7393939 | V87: 66.666667
A88: 87 | B88: بندر عباس | C88: تهران | D88: 37671844 | E88: پودر نارگیل | F88: 1 | G88: 0 | H88: 2 | I88: 3 | J88: 2 | K88: 5 | L88: -1 | M88: 1 | N88: 3 | O88: 20.721 | P88: 18.983 | Q88: 1.738 | R88: 20 | S88: 1036 | T88: 86 | U88: 8.3876261 | V88: 66.666667
A89: 88 | B89: بندر عباس | C89: تهران | D89: 37673516 | E89: بادام زمینی | F89: 6 | G89: 2 | H89: 4 | I89: 3 | J89: 2 | K89: 5 | L89: 1 | M89: 0 | N89: 12 | O89: 23.938 | P89: 22.416 | Q89: 1.522 | R89: 20 | S89: 1196 | T89: 76 | U89: 6.3580917 | V89: 33.333333
A90: 89 | B90: بندر عباس | C90: تهران | D90: 37673516 | E90: بادام زمینی | F90: 6 | G90: 2 | H90: 4 | I90: 3 | J90: 2 | K90: 5 | L90: 1 | M90: 0 | N90: 12 | O90: 24.074 | P90: 22.813 | Q90: 1.261 | R90: 25 | S90: 962 | T90: 50 | U90: 5.2380161 | V90: 33.333333
A91: 90 | B91: بندر عباس | C91: تهران | D91: 37673516 | E91: بادام زمینی | F91: 6 | G91: 2 | H91: 4 | I91: 3 | J91: 2 | K91: 5 | L91: 1 | M91: 0 | N91: 12 | O91: 24.75 | P91: 22.718 | Q91: 2.032 | R91: 25 | S91: 990 | T91: 81 | U91: 8.210101 | V91: 33.333333
A92: 91 | B92: بندر عباس | C92: تهران | D92: 37708966 | E92: قهوه دانه سبز | F92: 6 | G92: 9 | H92: 3 | I92: 3 | J92: 2 | K92: 5 | L92: 0 | M92: 1 | N92: 18 | O92: 24.75 | P92: 23.035 | Q92: 1.715 | R92: 25 | S92: 990 | T92: 68 | U92: 6.9292929 | V92: 16.666667
A93: 92 | B93: بندر عباس | C93: تهران | D93: 37708966 | E93: قهوه دانه سبز | F93: 6 | G93: 9 | H93: 3 | I93: 3 | J93: 2 | K93: 5 | L93: 0 | M93: 1 | N93: 18 | O93: 24.75 | P93: 23.47 | Q93: 1.28 | R93: 25 | S93: 990 | T93: 51 | U93: 5.1717172 | V93: 16.666667
A94: 93 | B94: بندر عباس | C94: اصفهان | D94: 37702603 | E94: قهوه دانه سبز | F94: 11 | G94: 7 | H94: 2 | I94: 3 | J94: 2 | K94: 4 | L94: -1 | M94: 1 | N94: 20 | O94: 24.75 | P94: 22.513 | Q94: 2.237 | R94: 25 | S94: 990 | T94: 89 | U94: 9.0383838 | V94: 10
...

Sheet شاخص مسیر
A1: گمرک مبدا | B1: انبار مقصد | C1: زمان استاندارد | D1: حداقل_زمان | E1: حداکثر_زمان | F1: زمان انتظاری PERT (روز) | G1: واریانس زمانی | H1: انحراف معیار زمانی (روز) | I1: ضریب تغییرات CV | J1: تعداد سفر ها | K1: سهم جریانی هر انبار | L1: تعداد تاخیر در هر مسیر | M1: احتمال بحران | N1: حداقل تأخیر بحران (D_min) | O1: حداکثر تأخیر بحران (D_max) | P1: توضیحات
A2: آستارا | B2: تهران | C2: 2 | D2: 1 | E2: 2 | F2: 1.8333333 | G2: 0.027777778 | H2: 0.16666667 | I2: 0.090909091 | J2: 10 | K2: 3.5842294 | L2: 2 | M2: 0.2 | N2: 1 | O2: 3 | P2: به دلیل کمبود داده در شبیه سازی لحاظ نمیشود
A3: آستارا | B3: دلیجان | C3: 2 | D3: 1 | E3: 2 | F3: 1.8333333 | G3: 0.027777778 | H3: 0.16666667 | I3: 0.090909091 | J3: 6 | K3: 2.1505376 | L3: 5 | M3: 0.83333333 | N3: 1 | O3: 1 | P3: به دلیل کمبود داده در شبیه سازی لحاظ نمیشود
A4: آستارا | B4: قزوین | C4: 1 | D4: 1 | E4: 2 | F4: 1.1666667 | G4: 0.027777778 | H4: 0.16666667 | I4: 0.14285714 | J4: 4 | K4: 1.4336918 | L4: 3 | M4: 0.75 | N4: 1 | O4: 1 | P4: به دلیل کمبود داده در شبیه سازی لحاظ نمیشود
A5: بندر عباس | B5: اصفهان | C5: 3 | D5: 2 | E5: 4 | F5: 3 | G5: 0.11111111 | H5: 0.33333333 | I5: 0.11111111 | J5: 37 | K5: 13.261649 | L5: 4 | M5: 0.10810811 | N5: 1 | O5: 2
A6: بندر عباس | B6: تهران | C6: 3 | D6: 2 | E6: 5 | F6: 3.1666667 | G6: 0.25 | H6: 0.5 | I6: 0.15789474 | J6: 103 | K6: 36.917563 | L6: 24 | M6: 0.23300971 | N6: 1 | O6: 2
A7: بندر عباس | B7: زرندیه (مرکزی) | C7: 2 | D7: 1 | E7: 3 | F7: 2 | G7: 0.11111111 | H7: 0.33333333 | I7: 0.16666667 | J7: 32 | K7: 11.469534 | L7: 16 | M7: 0.5 | N7: 1 | O7: 2
A8: بندر عباس | B8: ساری | C8: 4 | D8: 3 | E8: 5 | F8: 4 | G8: 0.11111111 | H8: 0.33333333 | I8: 0.083333333 | J8: 8 | K8: 2.8673835 | L8: 2 | M8: 0.25 | N8: 1 | O8: 1 | P8: به دلیل کمبود داده در شبیه سازی لحاظ نمیشود
A9: بندر عباس | B9: ساوه | C9: 3 | D9: 2 | E9: 4 | F9: 3 | G9: 0.11111111 | H9: 0.33333333 | I9: 0.11111111 | J9: 9 | K9: 3.2258065 | L9: 4 | M9: 0.44444444 | N9: 1 | O9: 1 | P9: به دلیل کمبود داده در شبیه سازی لحاظ نمیشود
A10: بندر عباس | B10: مامونیه | C10: 3 | D10: 2 | E10: 4 | F10: 3 | G10: 0.11111111 | H10: 0.33333333 | I10: 0.11111111 | J10: 4 | K10: 1.4336918 | L10: 1 | M10: 0.25 | N10: 1 | O10: 1 | P10: به دلیل کمبود داده در شبیه سازی لحاظ نمیشود
A11: بوشهر | B11: دلیجان | C11: 2 | D11: 1 | E11: 3 | F11: 2 | G11: 0.11111111 | H11: 0.33333333 | I11: 0.16666667 | J11: 6 | K11: 2.1505376 | L11: 4 | M11: 0.66666667 | N11: 1 | O11: 2 | P11: به دلیل کمبود داده در شبیه سازی لحاظ نمیشود
A12: بوشهر | B12: ساوه | C12: 2 | D12: 1 | E12: 3 | F12: 2 | G12: 0.11111111 | H12: 0.33333333 | I12: 0.16666667 | J12: 4 | K12: 1.4336918 | L12: 4 | M12: 1 | N12: 1 | O12: 3 | P12: به دلیل کمبود داده در شبیه سازی لحاظ نمیشود
A13: سرخس | B13: اصفهان | C13: 3 | D13: 2 | E13: 4 | F13: 3 | G13: 0.11111111 | H13: 0.33333333 | I13: 0.11111111 | J13: 3 | K13: 1.0752688 | L13: 1 | M13: 0.33333333 | N13: 1 | O13: 1 | P13: به دلیل کمبود داده در شبیه سازی لحاظ نمیشود
A14: سرخس | B14: تهران | C14: 3 | D14: 2 | E14: 4 | F14: 3 | G14: 0.11111111 | H14: 0.33333333 | I14: 0.11111111 | J14: 13 | K14: 4.6594982 | L14: 4 | M14: 0.30769231 | N14: 1 | O14: 2 | P14: به دلیل کمبود داده در شبیه سازی لحاظ نمیشود
A15: سرخس | B15: قزوین | C15: 4 | D15: 3 | E15: 5 | F15: 4 | G15: 0.11111111 | H15: 0.33333333 | I15: 0.083333333 | J15: 4 | K15: 1.4336918 | L15: 0 | M15: 0 | N15: 0 | O15: 0 | P15: به دلیل کمبود داده در شبیه سازی لحاظ نمیشود
A16: چابهار | B16: اصفهان | C16: 3 | D16: 2 | E16: 4 | F16: 3 | G16: 0.11111111 | H16: 0.33333333 | I16: 0.11111111 | J16: 8 | K16: 2.8673835 | L16: 2 | M16: 0.25 | N16: 1 | O16: 1 | P16: به دلیل کمبود داده در شبیه سازی لحاظ نمیشود
A17: چابهار | B17: تهران | C17: 3 | D17: 2 | E17: 4 | F17: 3 | G17: 0.11111111 | H17: 0.33333333 | I17: 0.11111111 | J17: 11 | K17: 3.9426523 | L17: 5 | M17: 0.45454545 | N17: 1 | O17: 2 | P17: به دلیل کمبود داده در شبیه سازی لحاظ نمیشود
A18: چابهار | B18: مامونیه | C18: 3 | D18: 2 | E18: 4 | F18: 3 | G18: 0.11111111 | H18: 0.33333333 | I18: 0.11111111 | J18: 6 | K18: 2.1505376 | L18: 1 | M18: 0.16666667 | N18: 1 | O18: 1 | P18: به دلیل کمبود داده در شبیه سازی لحاظ نمیشود
A19: چابهار | B19: مشهد | C19: 4 | D19: 3 | E19: 5 | F19: 4 | G19: 0.11111111 | H19: 0.33333333 | I19: 0.083333333 | J19: 11 | K19: 3.9426523 | L19: 2 | M19: 0.18181818 | N19: 1 | O19: 1 | P19: به دلیل کمبود داده در شبیه سازی لحاظ نمیشود
A21: نام کالا در پایگاه داده | B21: وزن واحد بسته (kg)
A22: تخمه آفتابگردان | B22: 20
A23: تخمه كدو | B23: 25
A24: زردچوبه | B24: 50
A25: زنجبیل | B25: 50
A26: عدس درشت روس | B26: 25
A27: عدس درشت کانادایی | B27: 25
A28: قهوه دانه سبز | B28: 60
A29: بادام زمینی | B29: 25
A30: فلفل سیاه | B30: 25
A31: پودر نارگیل | B31: 25
A32: شکر | B32: 1200
A33: چای | B33: 50
... A37: انواع نخ | B37: 25

Sheet شبیه سازی مسیر بندر به اصفهان
B1: مدل شبیه‌سازی مونت‌کارلو لیدتایم حمل: بندر عباس به اصفهان
B3: پارامترهای مسیر و مدل | F3: شاخص‌های کلیدی عملکرد (KPI) | I3: شماره تکرار (i) | J3: زمان پایه Beta-PERT (T_base) | K3: کلید بحران برنولی (S) | L3: تأخیر مازاد بحران (ΔT) | M3: لیدتایم کل مسیر (T_Total) | N3: تحویل به‌موقع (OTD Flag)
B4: زمان تعهد قانونی (SLA) | C4: 3 | F4: میانگین زمان حمل (T_avg) | G4: 3.172809 | I4: 1 | J4: 2.9406898 | K4: 0 | L4: 0 | M4: 2.9406898 | N4: 1
B5: حداقل زمان فیزیکی (a) | C5: 2 | F5: انحراف معیار زمان حمل (SD) | G5: 0.61840019 | I5: 2 | J5: 3.2644021 | K5: 0 | L5: 0 | M5: 3.2644021 | N5: 0
B6: محتمل‌ترین زمان (m) | C6: 3 | F6: نرخ تحویل به موقع (OTD) | G6: 0.46 | I6: 3 | J6: 2.9737353 | K6: 1 | L6: 1.5331142 | M6: 4.5068495 | N6: 0
B7: حداکثر زمان نرمال (b) | C7: 4 | F7: ضریب تغییرات (CV) | G7: 0.19490622 | I7: 4 | J7: 2.7767805 | K7: 0 | L7: 0 | M7: 2.7767805 | N7: 1
B8: آلفای بتا PERT (α) | C8: 3 | F8: زمان در معرض ریسک (TaR 95%) | G8: 4.5819308 | I8: 5 | J8: 3.7073997 | K8: 0 | L8: 0 | M8: 3.7073997 | N8: 0
B9: بتای بتا PERT (β) | C9: 3 | F9: زمان در معرض ریسک شرطی (CTaR 95%) | G9: 4.8954981 | I9: 6 | J9: 2.8923915 | K9: 0 | L9: 0 | M9: 2.8923915 | N9: 1
B10: احتمال رخداد بحران (p) | C10: 0.10810811 | F10: شکاف بحران (Crisis Gap) | G10: 0.31356729 | I10: 7 | J10: 3.4745638 | K10: 0 | L10: 0 | M10: 3.4745638 | N10: 0
B11: حداقل تأخیر بحران (D_min) | C11: 1 | F11: شاخص بافر زمانی (BI %) | G11: 0.52731027 | I11: 8 | J11: 2.9642743 | K11: 0 | L11: 0 | M11: 2.9642743 | N11: 1
B12: حداکثر تأخیر بحران (D_max) | C12: 2 | F12: شاخص زمان برنامه‌ریزی (PTI) | G12: 1.5273103 | I12: 9 | J12: 3.3218809 | K12: 0 | L12: 0 | M12: 3.3218809 | N12: 0
B13: تعداد تکرار شبیه‌سازی (N) | C13: 1000 | F13: بافر اطمینان مطلق (روز) | G13: 1.4091218 | I13: 10 | J13: 3.7246551 | K13: 0 | L13: 0 | M13: 3.7246551 | N13: 0
I14: 11 | J14: 2.6541543 | K14: 0 | L14: 0 | M14: 2.6541543 | N14: 1
I15: 12 | J15: 2.6523913 | K15: 0 | L15: 0 | M15: 2.6523913 | N15: 1
I16: 13 | J16: 2.9217447 | K16: 0 | L16: 0 | M16: 2.9217447 | N16: 1
F17: بهینه‌سازی تعهد SLA و بافر داینامیک | I17: 14 | J17: 2.5617252 | K17: 0 | L17: 0 | M17: 2.5617252 | N17: 1
F18: تارگت تحویل 50% (P50) | G18: 3.0543688 | I18: 15 | J18: 2.7359942 | K18: 0 | L18: 0 | M18: 2.7359942 | N18: 1
F19: تارگت تحویل 90% (P90) | G19: 4.0316876 | I19: 16 | J19: 2.6238718 | K19: 0 | L19: 0 | M19: 2.6238718 | N19: 1
F20: تارگت تحویل 95% (P95) | G20: 4.5819308 | I20: 17 | J20: 2.4456896 | K20: 0 | L20: 0 | M20: 2.4456896 | N20: 1
I21: 18 | J21: 2.793319 | K21: 0 | L21: 0 | M21: 2.793319 | N21: 1
I22: 19 | J22: 2.69521 | K22: 0 | L22: 0 | M22: 2.69521 | N22: 1
I23: 20 | J23: 3.4328521 | K23: 0 | L23: 0 | M23: 3.4328521 | N23: 0
I24: 21 | J24: 3.244855 | K24: 0 | L24: 0 | M24: 3.244855 | N24: 0
I25: 22 | J25: 3.3950665 | K25: 0 | L25: 0 | M25: 3.3950665 | N25: 0
I26: 23 | J26: 3.359539 | K26: 0 | L26: 0 | M26: 3.359539 | N26: 0
I27: 24 | J27: 3.0952593 | K27: 1 | L27: 1.6920001 | M27: 4.7872594 | N27: 0
I28: 25 | J28: 2.4622257 | K28: 0 | L28: 0 | M28: 2.4622257 | N28: 1
I29: 26 | J29: 3.6015985 | K29: 1 | L29: 1.0442857 | M29: 4.6458842 | N29: 0
I30: 27 | J30: 2.5278228 | K30: 0 | L30: 0 | M30: 2.5278228 | N30: 1
I31: 28 | J31: 3.1033103 | K31: 0 | L31: 0 | M31: 3.1033103 | N31: 0
I32: 29 | J32: 2.9592214 | K32: 0 | L32: 0 | M32: 2.9592214 | N32: 1
... I1003: 1000 | J1003: 3.7286606 | K1003: 1 | L1003: 1.0620077 | M1003: 4.7906684 | N1003: 0

Sheet شبیه سازی مسیر بندر به تهران
B1: مدل شبیه‌سازی مونت‌کارلو لیدتایم حمل: بندر عباس به تهران
B3: پارامترهای مسیر و مدل | F3: شاخص‌های کلیدی عملکرد (KPI) | I3: شماره تکرار (i) | J3: زمان پایه Beta-PERT (T_base) | K3: کلید بحران برنولی (S) | L3: تأخیر مازاد بحران (ΔT) | M3: لیدتایم کل مسیر (T_Total) | N3: تحویل به‌موقع (OTD Flag)
B4: زمان تعهد قانونی (SLA) | C4: 3 | F4: میانگین زمان حمل (T_avg) | G4: 3.5301157 | I4: 1 | J4: 3.7766595 | K4: 0 | L4: 0 | M4: 3.7766595 | N4: 0
B5: حداقل زمان فیزیکی (a) | C5: 2 | F5: انحراف معیار زمان حمل (SD) | G5: 0.85842617 | I5: 2 | J5: 3.2029891 | K5: 0 | L5: 0 | M5: 3.2029891 | N5: 0
B6: محتمل‌ترین زمان (m) | C6: 3 | F6: نرخ تحویل به موقع (OTD) | G6: 0.332 | I6: 3 | J6: 2.973098 | K6: 0 | L6: 0 | M6: 2.973098 | N6: 1
B7: حداکثر زمان نرمال (b) | C7: 5 | F7: ضریب تغییرات (CV) | G7: 0.24317225 | I7: 4 | J7: 3.916687 | K7: 0 | L7: 0 | M7: 3.916687 | N7: 0
B8: آلفای بتا PERT (α) | C8: 2.3333333 | F8: زمان در معرض ریسک (TaR 95%) | G8: 5.156177 | I8: 5 | J8: 2.7290744 | K8: 0 | L8: 0 | M8: 2.7290744 | N8: 1
B9: بتای بتا PERT (β) | C9: 3.6666667 | F9: زمان در معرض ریسک شرطی (CTaR 95%) | G9: 5.4820504 | I9: 6 | J9: 2.9984552 | K9: 0 | L9: 0 | M9: 2.9984552 | N9: 1
B10: احتمال رخداد بحران (p) | C10: 0.23300971 | F10: شکاف بحران (Crisis Gap) | G10: 0.32587348 | I10: 7 | J10: 2.8399045 | K10: 0 | L10: 0 | M10: 2.8399045 | N10: 1
B11: حداقل تأخیر بحران (D_min) | C11: 1 | F11: شاخص بافر زمانی (BI %) | G11: 0.71872566 | I11: 8 | J11: 2.8986226 | K11: 1 | L11: 1.2513407 | M11: 4.1499632 | N11: 0
B12: حداکثر تأخیر بحران (D_max) | C12: 2 | F12: شاخص زمان برنامه‌ریزی (PTI) | G12: 1.7187257 | I12: 9 | J12: 2.753296 | K12: 0 | L12: 0 | M12: 2.753296 | N12: 1
B13: تعداد تکرار شبیه‌سازی (N) | C13: 1000 | F13: بافر اطمینان مطلق (روز) | G13: 1.6260613 | I13: 10 | J13: 2.6552031 | K13: 0 | L13: 0 | M13: 2.6552031 | N13: 1
I14: 11 | J14: 3.7091078 | K14: 1 | L14: 1.446423 | M14: 5.1555308 | N14: 0
I15: 12 | J15: 3.8048225 | K15: 0 | L15: 0 | M15: 3.8048225 | N15: 0
I16: 13 | J16: 2.6583581 | K16: 1 | L16: 1.3944144 | M16: 4.0527725 | N16: 0
F17: بهینه‌سازی تعهد SLA و بافر داینامیک | I17: 14 | J17: 3.1347477 | K17: 0 | L17: 0 | M17: 3.1347477 | N17: 0
F18: تارگت تحویل 50% (P50) | G18: 3.3722418 | I18: 15 | J18: 2.1877869 | K18: 0 | L18: 0 | M18: 2.1877869 | N18: 1
F19: تارگت تحویل 90% (P90) | G19: 4.7945444 | I19: 16 | J19: 2.4205922 | K19: 0 | L19: 0 | M19: 2.4205922 | N19: 1
F20: تارگت تحویل 95% (P95) | G20: 5.156177 | I20: 17 | J20: 2.1827769 | K20: 0 | L20: 0 | M20: 2.1827769 | N20: 1
I21: 18 | J21: 2.732703 | K21: 0 | L21: 0 | M21: 2.732703 | N21: 1
I22: 19 | J22: 2.9457205 | K22: 0 | L22: 0 | M22: 2.9457205 | N22: 1
I23: 20 | J23: 3.0145452 | K23: 0 | L23: 0 | M23: 3.0145452 | N23: 0
I24: 21 | J24: 3.4668132 | K24: 0 | L24: 0 | M24: 3.4668132 | N24: 0
I25: 22 | J25: 4.0481863 | K25: 0 | L25: 0 | M25: 4.0481863 | N25: 0
I26: 23 | J26: 3.0829062 | K26: 0 | L26: 0 | M26: 3.0829062 | N26: 0
I27: 24 | J27: 3.6409226 | K27: 0 | L27: 0 | M27: 3.6409226 | N27: 0
I28: 25 | J28: 3.1753964 | K28: 0 | L28: 0 | M28: 3.1753964 | N28: 0
I29: 26 | J29: 2.7178931 | K29: 0 | L29: 0 | M29: 2.7178931 | N29: 1
I30: 27 | J30: 3.3069101 | K30: 1 | L30: 1.130617 | M30: 4.4375271 | N30: 0
I31: 28 | J31: 2.9447053 | K31: 1 | L31: 1.5544166 | M31: 4.4991219 | N31: 0
I32: 29 | J32: 4.1554504 | K32: 0 | L32: 0 | M32: 4.1554504 | N32: 0
... I1003: 1000 | J1003: 2.4090041 | K1003: 0 | L1003: 0 | M1003: 2.4090041 | N1003: 1

Sheet شبیه سازی مسیر بندر به زرندیه
B1: مدل شبیه‌سازی مونت‌کارلو لیدتایم حمل: بندر عباس به زرندیه
B3: پارامترهای مسیر و مدل | F3: شاخص‌های کلیدی عملکرد (KPI) | I3: شماره تکرار (i) | J3: زمان پایه Beta-PERT (T_base) | K3: کلید بحران برنولی (S) | L3: تأخیر مازاد بحران (ΔT) | M3: لیدتایم کل مسیر (T_Total) | N3: تحویل به‌موقع (OTD Flag)
B4: زمان تعهد قانونی (SLA) | C4: 2 | F4: میانگین زمان حمل (T_avg) | G4: 2.7354483 | I4: 1 | J4: 1.7052653 | K4: 0 | L4: 0 | M4: 1.7052653 | N4: 1
B5: حداقل زمان فیزیکی (a) | C5: 1 | F5: انحراف معیار زمان حمل (SD) | G5: 0.85039403 | I5: 2 | J5: 1.5943914 | K5: 1 | L5: 1.050912 | M5: 2.6453034 | N5: 0
B6: محتمل‌ترین زمان (m) | C6: 2 | F6: نرخ تحویل به موقع (OTD) | G6: 0.259 | I6: 3 | J6: 2.1503946 | K6: 1 | L6: 1.6152876 | M6: 3.7656823 | N6: 0
B7: حداکثر زمان نرمال (b) | C7: 3 | F7: ضریب تغییرات (CV) | G7: 0.31087922 | I7: 4 | J7: 1.9351068 | K7: 1 | L7: 1.3353262 | M7: 3.2704329 | N7: 0
B8: آلفای بتا PERT (α) | C8: 3 | F8: زمان در معرض ریسک (TaR 95%) | G8: 4.0826931 | I8: 5 | J8: 1.9894089 | K8: 1 | L8: 1.7577272 | M8: 3.7471361 | N8: 0
B9: بتای بتا PERT (β) | C9: 3 | F9: زمان در معرض ریسک شرطی (CTaR 95%) | G9: 4.254034 | I9: 6 | J9: 1.9924957 | K9: 1 | L9: 1.85355 | M9: 3.8460457 | N9: 0
B10: احتمال رخداد بحران (p) | C10: 0.5 | F10: شکاف بحران (Crisis Gap) | G10: 0.17134088 | I10: 7 | J10: 2.3277531 | K10: 1 | L10: 1.459669 | M10: 3.7874221 | N10: 0
B11: حداقل تأخیر بحران (D_min) | C11: 1 | F11: شاخص بافر زمانی (BI %) | G11: 1.0413465 | I11: 8 | J11: 1.5732488 | K11: 1 | L11: 1.2538761 | M11: 2.8271249 | N11: 0
B12: حداکثر تأخیر بحران (D_max) | C12: 2 | F12: شاخص زمان برنامه‌ریزی (PTI) | G12: 2.0413465 | I12: 9 | J12: 1.9847906 | K12: 1 | L12: 1.253302 | M12: 3.2380926 | N12: 0
B13: تعداد تکرار شبیه‌سازی (N) | C13: 1000 | F13: بافر اطمینان مطلق (روز) | G13: 1.3472448 | I13: 10 | J13: 2.1086631 | K13: 0 | L13: 0 | M13: 2.1086631 | N13: 0
I14: 11 | J14: 2.3539312 | K14: 1 | L14: 1.6495855 | M14: 4.0035168 | N14: 0
I15: 12 | J15: 2.25088 | K15: 1 | L15: 1.8417351 | M15: 4.0926151 | N15: 0
I16: 13 | J16: 1.6071368 | K16: 1 | L16: 1.2602458 | M16: 2.8673826 | N16: 0
F17: بهینه‌سازی تعهد SLA و بافر داینامیک | I17: 14 | J17: 2.1333783 | K17: 1 | L17: 1.6620696 | M17: 3.7954479 | N17: 0
F18: تارگت تحویل 50% (P50) | G18: 2.6455873 | I18: 15 | J18: 2.6502712 | K18: 1 | L18: 1.4776789 | M18: 4.1279501 | N18: 0
F19: تارگت تحویل 90% (P90) | G19: 3.8715566 | I19: 16 | J19: 1.6855007 | K19: 1 | L19: 1.4405938 | M19: 3.1260945 | N19: 0
F20: تارگت تحویل 95% (P95) | G20: 4.0826931 | I20: 17 | J20: 1.9770293 | K20: 0 | L20: 0 | M20: 1.9770293 | N20: 1
I21: 18 | J21: 1.7117405 | K21: 1 | L21: 1.6110126 | M21: 3.3227531 | N21: 0
I22: 19 | J22: 2.2681166 | K22: 0 | L22: 0 | M22: 2.2681166 | N22: 0
I23: 20 | J23: 2.1275473 | K23: 0 | L23: 0 | M23: 2.1275473 | N23: 0
I24: 21 | J24: 1.6127072 | K24: 1 | L24: 1.7672695 | M24: 3.3799767 | N24: 0
I25: 22 | J25: 1.3440379 | K25: 1 | L25: 1.9414705 | M25: 3.2855084 | N25: 0
I26: 23 | J26: 2.3414226 | K26: 0 | L26: 0 | M26: 2.3414226 | N26: 0
I27: 24 | J27: 2.1366017 | K27: 1 | L27: 1.6306744 | M27: 3.7672761 | N27: 0
I28: 25 | J28: 1.6063076 | K28: 0 | L28: 0 | M28: 1.6063076 | N28: 1
I29: 26 | J29: 2.0312143 | K29: 0 | L29: 0 | M29: 2.0312143 | N29: 0
I30: 27 | J30: 2.2848713 | K30: 0 | L30: 0 | M30: 2.2848713 | N30: 0
I31: 28 | J31: 1.6613491 | K31: 1 | L31: 1.3150438 | M31: 2.9763929 | N31: 0
I32: 29 | J32: 1.8859924 | K32: 0 | L32: 0 | M32: 1.8859924 | N32: 1
... I1003: 1000 | J1003: 2.5364229 | K1003: 0 | L1003: 0 | M1003: 2.5364229 | N1003: 0

Sheet پایگاه داده باکس پلات
A1: فاز کل چرخه لجستیک | H1: فاز یک: اظهار تا ترخیص گمرکی | O1: فاز دو: ترخیص تا بارگیری | V1: فاز سه: حمل بین شهری تا انبار مقصد
A2: فاز چهار: کل چرخه لجستیک | آستارا به تهران | B2: فاز چهار: کل چرخه لجستیک | بندرعباس به اصفهان | C2: فاز چهار: کل چرخه لجستیک | بندرعباس به تهران | D2: فاز چهار: کل چرخه لجستیک | بندرعباس به زرندیه | E2: فاز چهار: کل چرخه لجستیک | چابهار به تهران | F2: فاز چهار: کل چرخه لجستیک | چابهار به مشهد | G2: فاز چهار: کل چرخه لجستیک | کل فاز (بدون لحاظ مسیر) | H2: فاز یک: اظهار تا ترخیص گمرکی | آستارا به تهران | I2: فاز یک: اظهار تا ترخیص گمرکی | بندرعباس به اصفهان | J2: فاز یک: اظهار تا ترخیص گمرکی | بندرعباس به تهران | K2: فاز یک: اظهار تا ترخیص گمرکی | بندرعباس به زرندیه | L2: فاز یک: اظهار تا ترخیص گمرکی | چابهار به تهران | M2: فاز یک: اظهار تا ترخیص گمرکی | چابهار به مشهد | N2: فاز یک: اظهار تا ترخیص گمرکی | کل فاز (بدون لحاظ مسیر) | O2: فاز دو: ترخیص تا بارگیری | آستارا به تهران | P2: فاز دو: ترخیص تا بارگیری | بندرعباس به اصفهان | Q2: فاز دو: ترخیص تا بارگیری | بندرعباس به تهران | R2: فاز دو: ترخیص تا بارگیری | بندرعباس به زرندیه | S2: فاز دو: ترخیص تا بارگیری | چابهار به تهران | T2: فاز دو: ترخیص تا بارگیری | چابهار به مشهد | U2: فاز دو: ترخیص تا بارگیری | کل فاز (بدون لحاظ مسیر) | V2: فاز سه: حمل بین شهری تا انبار مقصد | آستارا به تهران | W2: فاز سه: حمل بین شهری تا انبار مقصد | بندرعباس به اصفهان | Y2: فاز سه: حمل بین شهری تا انبار مقصد | بندرعباس به زرندیه | Z2: فاز سه: حمل بین شهری تا انبار مقصد | چابهار به تهران | AA2: فاز سه: حمل بین شهری تا انبار مقصد | چابهار به مشهد | AB2: فاز سه: حمل بین شهری تا انبار مقصد | کل فاز (بدون لحاظ مسیر) | AD2: =IF(ISNA($AD3), NA(),داشبرد!$D$5) -> فاز چهار: کل چرخه لجستیک | کل فاز (بدون لحاظ مسیر)
A3: 183 | B3: 10 | C3: 12 | D3: 13 | E3: 18 | F3: 17 | G3: 10 | H3: 38 | I3: 7 | J3: 7 | K3: 10 | L3: 12 | M3: 2 | N3: 7 | O3: 143 | P3: 0 | Q3: 0 | R3: 1 | S3: 4 | T3: 10 | U3: 2 | V3: 2 | W3: 3 | X3: 5 | Y3: 2 | Z3: 2 | AA3: 5 | AB3: 3 | AD3: =IF(ISNUMBER(INDEX($A3:$AB3, MATCH(داشبرد!$D$5, $A$2:$AB$2, 0))), INDEX($A3:$AB3, MATCH(داشبرد!$D$5, $A$2:$AB$2, 0)), NA()) -> 10
A4: 183 | B4: 10 | C4: 9 | D4: 14 | E4: 20 | F4: 16 | G4: 10 | H4: 38 | I4: 7 | J4: 7 | K4: 10 | L4: 12 | M4: 2 | N4: 7 | O4: 143 | P4: 0 | Q4: 0 | R4: 1 | S4: 4 | T4: 10 | U4: 3 | V4: 2 | W4: 3 | X4: 2 | Y4: 3 | Z4: 4 | AA4: 4 | AB4: 3 | AD4: =IF(ISNUMBER(INDEX($A4:$AB4, MATCH(داشبرد!$D$5, $A$2:$AB$2, 0))), INDEX($A4:$AB4, MATCH(داشبرد!$D$5, $A$2:$AB$2, 0)), NA()) -> 10
A5: 42 | B5: 9 | C5: 8 | D5: 14 | E5: 19 | F5: 16 | G5: 9 | H5: 38 | I5: 7 | J5: 2 | K5: 10 | L5: 12 | M5: 2 | N5: 7 | O5: 1 | P5: 0 | Q5: 2 | R5: 1 | S5: 4 | T5: 10 | U5: 3 | V5: 3 | W5: 2 | X5: 4 | Y5: 3 | Z5: 3 | AA5: 4 | AB5: 2 | AD5: =IF(ISNUMBER(INDEX($A5:$AB5, MATCH(داشبرد!$D$5, $A$2:$AB$2, 0))), INDEX($A5:$AB5, MATCH(داشبرد!$D$5, $A$2:$AB$2, 0)), NA()) -> 9
A6: 67 | B6: 9 | C6: 7 | D6: 14 | E6: 6 | F6: 18 | G6: 12 | H6: 65 | I6: 7 | J6: 2 | K6: 10 | L6: 3 | M6: 12 | N6: 7 | O6: 0 | P6: 0 | Q6: 2 | R6: 1 | S6: 1 | T6: 2 | U6: 2 | V6: 2 | W6: 2 | X6: 3 | Y6: 3 | Z6: 2 | AA6: 4 | AB6: 5 | AD6: =IF(ISNUMBER(INDEX($A6:$AB6, MATCH(داشبرد!$D$5, $A$2:$AB$2, 0))), INDEX($A6:$AB6, MATCH(داشبرد!$D$5, $A$2:$AB$2, 0)), NA()) -> 12
A7: 67 | B7: 10 | C7: 6 | D7: 12 | E7: 6 | F7: 19 | G7: 9 | H7: 65 | I7: 7 | J7: 2 | K7: 10 | L7: 3 | M7: 12 | N7: 7 | O7: 0 | P7: 0 | Q7: 2 | R7: 0 | S7: 1 | T7: 2 | U7: 2 | V7: 2 | W7: 3 | X7: 2 | Y7: 2 | Z7: 2 | AA7: 5 | AB7: 2 | AD7: =IF(ISNUMBER(INDEX($A7:$AB7, MATCH(داشبرد!$D$5, $A$2:$AB$2, 0))), INDEX($A7:$AB7, MATCH(داشبرد!$D$5, $A$2:$AB$2, 0)), NA()) -> 9
A8: 67 | B8: 8 | C8: 6 | D8: 13 | E8: 8 | F8: 18 | G8: 10 | H8: 65 | I8: 4 | J8: 1 | K8: 10 | L8: 3 | M8: 12 | N8: 7 | O8: 0 | P8: 1 | Q8: 4 | R8: 0 | S8: 1 | T8: 2 | U8: 2 | V8: 2 | W8: 3 | X8: 1 | Y8: 3 | Z8: 4 | AA8: 4 | AB8: 3 | AD8: =IF(ISNUMBER(INDEX($A8:$AB8, MATCH(داشبرد!$D$5, $A$2:$AB$2, 0))), INDEX($A8:$AB8, MATCH(داشبرد!$D$5, $A$2:$AB$2, 0)), NA()) -> 10
A9: 19 | B9: 7 | C9: 9 | D9: 12 | E9: 11 | F9: 12 | G9: 9 | H9: 14 | I9: 4 | J9: 1 | K9: 10 | L9: 7 | M9: 3 | N9: 7 | O9: 1 | P9: 1 | Q9: 3 | R9: 0 | S9: 1 | T9: 5 | U9: 2 | V9: 4 | W9: 2 | X9: 5 | Y9: 2 | Z9: 3 | AA9: 4 | AB9: 2 | AD9: =IF(ISNUMBER(INDEX($A9:$AB9, MATCH(داشبرد!$D$5, $A$2:$AB$2, 0))), INDEX($A9:$AB9, MATCH(داشبرد!$D$5, $A$2:$AB$2, 0)), NA()) -> 9
A10: 18 | B10: 6 | C10: 6 | D10: 13 | E10: 12 | F10: 12 | G10: 40 | H10: 14 | I10: 4 | J10: 1 | K10: 10 | L10: 7 | M10: 3 | N10: 38 | O10: 2 | P10: 1 | Q10: 3 | R10: 0 | S10: 2 | T10: 5 | U10: 2 | V10: 2 | W10: 1 | X10: 2 | Y10: 3 | Z10: 3 | AA10: 4 | AB10: 2 | AD10: =IF(ISNUMBER(INDEX($A10:$AB10, MATCH(داشبرد!$D$5, $A$2:$AB$2, 0))), INDEX($A10:$AB10, MATCH(داشبرد!$D$5, $A$2:$AB$2, 0)), NA()) -> 40
A11: 18 | B11: 8 | C11: 8 | D11: 5 | E11: 14 | F11: 12 | G11: 40 | H11: 14 | I11: 3 | J11: 1 | K11: 3 | L11: 7 | M11: 3 | N11: 38 | O11: 2 | P11: 3 | Q11: 3 | R11: 0 | S11: 3 | T11: 5 | U11: 3 | V11: 2 | W11: 2 | X11: 4 | Y11: 2 | Z11: 4 | AA11: 4 | AB11: 2 | AD11: =IF(ISNUMBER(INDEX($A11:$AB11, MATCH(داشبرد!$D$5, $A$2:$AB$2, 0))), INDEX($A11:$AB11, MATCH(داشبرد!$D$5, $A$2:$AB$2, 0)), NA()) -> 40
A12: 21 | B12: 7 | C12: 7 | D12: 5 | E12: 15 | F12: 11 | G12: 39 | H12: 14 | I12: 3 | J12: 3 | K12: 3 | L12: 7 | M12: 3 | N12: 38 | O12: 2 | P12: 2 | Q12: 1 | R12: 0 | S12: 3 | T12: 5 | U12: 3 | V12: 5 | W12: 2 | X12: 3 | Y12: 2 | Z12: 5 | AA12: 3 | AB12: 1 | AD12: =IF(ISNUMBER(INDEX($A12:$AB12, MATCH(داشبرد!$D$5, $A$2:$AB$2, 0))), INDEX($A12:$AB12, MATCH(داشبرد!$D$5, $A$2:$AB$2, 0)), NA()) -> 39
B13: 7 | C13: 6 | D13: 5 | E13: 14 | F13: 11 | G13: 40 | I13: 3 | J13: 3 | K13: 3 | L13: 7 | M13: 3 | N13: 38 | P13: 2 | Q13: 1 | R13: 0 | S13: 3 | T13: 5 | U13: 1 | W13: 2 | X13: 2 | Y13: 2 | Z13: 4 | AA13: 3 | AB13: 2 | AD13: =IF(ISNUMBER(INDEX($A13:$AB13, MATCH(داشبرد!$D$5, $A$2:$AB$2, 0))), INDEX($A13:$AB13, MATCH(داشبرد!$D$5, $A$2:$AB$2, 0)), NA()) -> 40
B14: 9 | C14: 7 | D14: 8 | G14: 183 | I14: 3 | J14: 3 | K14: 5 | N14: 38 | P14: 3 | Q14: 1 | R14: 0 | U14: 1 | W14: 3 | X14: 3 | Y14: 3 | AB14: 2 | AD14: =IF(ISNUMBER(INDEX($A14:$AB14, MATCH(داشبرد!$D$5, $A$2:$AB$2, 0))), INDEX($A14:$AB14, MATCH(داشبرد!$D$5, $A$2:$AB$2, 0)), NA()) -> 183
B15: 9 | C15: 15 | D15: 8 | G15: 183 | I15: 3 | J15: 5 | K15: 5 | N15: 38 | P15: 3 | Q15: 7 | R15: 0 | U15: 3 | W15: 3 | X15: 3 | Y15: 3 | AB15: 2 | AD15: =IF(ISNUMBER(INDEX($A15:$AB15, MATCH(داشبرد!$D$5, $A$2:$AB$2, 0))), INDEX($A15:$AB15, MATCH(داشبرد!$D$5, $A$2:$AB$2, 0)), NA()) -> 183
B16: 10 | C16: 14 | D16: 8 | G16: 182 | I16: 3 | J16: 5 | K16: 5 | N16: 38 | P16: 3 | Q16: 7 | R16: 0 | U16: 4 | W16: 4 | X16: 2 | Y16: 3 | AB16: 1 | AD16: =IF(ISNUMBER(INDEX($A16:$AB16, MATCH(داشبرد!$D$5, $A$2:$AB$2, 0))), INDEX($A16:$AB16, MATCH(داشبرد!$D$5, $A$2:$AB$2, 0)), NA()) -> 182
B17: 11 | C17: 9 | D17: 7 | G17: 8 | I17: 8 | J17: 4 | K17: 5 | N17: 2 | P17: 1 | Q17: 2 | R17: 0 | U17: 4 | W17: 2 | X17: 3 | Y17: 2 | AB17: 4 | AD17: =IF(ISNUMBER(INDEX($A17:$AB17, MATCH(داشبرد!$D$5, $A$2:$AB$2, 0))), INDEX($A17:$AB17, MATCH(داشبرد!$D$5, $A$2:$AB$2, 0)), NA()) -> 8
B18: 12 | C18: 9 | D18: 10 | G18: 7 | I18: 8 | J18: 4 | K18: 5 | N18: 2 | P18: 1 | Q18: 2 | R18: 2 | U18: 5 | W18: 3 | X18: 3 | Y18: 3 | AB18: 3 | AD18: =IF(ISNUMBER(INDEX($A18:$AB18, MATCH(داشبرد!$D$5, $A$2:$AB$2, 0))), INDEX($A18:$AB18, MATCH(داشبرد!$D$5, $A$2:$AB$2, 0)), NA()) -> 7
B19: 12 | C19: 9 | D19: 12 | G19: 6 | I19: 8 | J19: 4 | K19: 5 | N19: 2 | P19: 1 | Q19: 2 | R19: 3 | U19: 5 | W19: 3 | X19: 3 | Y19: 4 | AB19: 2 | AD19: =IF(ISNUMBER(INDEX($A19:$AB19, MATCH(داشبرد!$D$5, $A$2:$AB$2, 0))), INDEX($A19:$AB19, MATCH(داشبرد!$D$5, $A$2:$AB$2, 0)), NA()) -> 6
B20: 11 | C20: 8 | D20: 10 | G20: 6 | I20: 2 | J20: 4 | K20: 5 | N20: 1 | P20: 6 | Q20: 1 | R20: 3 | U20: 5 | W20: 3 | X20: 3 | Y20: 2 | AB20: 1 | AD20: =IF(ISNUMBER(INDEX($A20:$AB20, MATCH(داشبرد!$D$5, $A$2:$AB$2, 0))), INDEX($A20:$AB20, MATCH(داشبرد!$D$5, $A$2:$AB$2, 0)), NA()) -> 6
B21: 11 | C21: 8 | D21: 10 | G21: 9 | I21: 2 | J21: 4 | K21: 5 | N21: 1 | P21: 6 | Q21: 1 | R21: 3 | U21: 3 | W21: 3 | X21: 3 | Y21: 2 | AB21: 5 | AD21: =IF(ISNUMBER(INDEX($A21:$AB21, MATCH(داشبرد!$D$5, $A$2:$AB$2, 0))), INDEX($A21:$AB21, MATCH(داشبرد!$D$5, $A$2:$AB$2, 0)), NA()) -> 9
B22: 26 | C22: 8 | D22: 11 | G22: 6 | I22: 15 | J22: 4 | K22: 5 | N22: 1 | P22: 9 | Q22: 1 | R22: 4 | U22: 3 | W22: 2 | X22: 3 | Y22: 2 | AB22: 2 | AD22: =IF(ISNUMBER(INDEX($A22:$AB22, MATCH(داشبرد!$D$5, $A$2:$AB$2, 0))), INDEX($A22:$AB22, MATCH(داشبرد!$D$5, $A$2:$AB$2, 0)), NA()) -> 6
B23: 24 | C23: 8 | D23: 11 | G23: 8 | I23: 15 | J23: 4 | K23: 5 | N23: 1 | P23: 8 | Q23: 1 | R23: 4 | U23: 4 | W23: 1 | X23: 3 | Y23: 2 | AB23: 4 | AD23: =IF(ISNUMBER(INDEX($A23:$AB23, MATCH(داشبرد!$D$5, $A$2:$AB$2, 0))), INDEX($A23:$AB23, MATCH(داشبرد!$D$5, $A$2:$AB$2, 0)), NA()) -> 8
B24: 25 | C24: 8 | D24: 12 | G24: 8 | I24: 15 | J24: 4 | K24: 5 | N24: 4 | P24: 8 | Q24: 1 | R24: 5 | U24: 4 | W24: 2 | X24: 3 | Y24: 2 | AB24: 3 | AD24: =IF(ISNUMBER(INDEX($A24:$AB24, MATCH(داشبرد!$D$5, $A$2:$AB$2, 0))), INDEX($A24:$AB24, MATCH(داشبرد!$D$5, $A$2:$AB$2, 0)), NA()) -> 8
B25: 25 | C25: 6 | D25: 12 | G25: 7 | I25: 15 | J25: 2 | K25: 5 | N25: 4 | P25: 8 | Q25: 1 | R25: 5 | U25: 4 | W25: 2 | X25: 3 | Y25: 2 | AB25: 2 | AD25: =IF(ISNUMBER(INDEX($A25:$AB25, MATCH(داشبرد!$D$5, $A$2:$AB$2, 0))), INDEX($A25:$AB25, MATCH(داشبرد!$D$5, $A$2:$AB$2, 0)), NA()) -> 7
... B28: 21 | C28: 11 | D28: 11 | G28: 6 | I28: 11 | J28: 5 | K28: 5 | N28: 3 | P28: 7 | Q28: 3 | R28: 3 | U28: 2 | W28: 3 | X28: 3 | Y28: 3 | AB28: 2 | AD28: =IF(ISNUMBER(INDEX($A28:$AB28, MATCH(داشبرد!$D$5, $A$2:$AB$2, 0))), INDEX($A28:$AB28, MATCH(داشبرد!$D$5, $A$2:$AB$2, 0)), NA()) -> 6
B29: 8 | C29: 11 | D29: 12 | G29: 7 | I29: 7 | J29: 5 | K29: 5 | N29: 3 | P29: 0 | Q29: 3 | R29: 4 | W29: 1 | X29: 3 | Y29: 3 | AB29: 3 | AD29: =IF(ISNUMBER(INDEX($A29:$AB29, MATCH(داشبرد!$D$5, $A$2:$AB$2, 0))), INDEX($A29:$AB29, MATCH(داشبرد!$D$5, $A$2:$AB$2, 0)), NA()) -> 7
B30: 9 | C30: 11 | D30: 12 | G30: 15 | I30: 7 | J30: 5 | K30: 5 | N30: 5 | P30: 0 | Q30: 3 | R30: 4 | W30: 2 | X30: 3 | Y30: 3 | AB30: 3 | AD30: =IF(ISNUMBER(INDEX($A30:$AB30, MATCH(داشبرد!$D$5, $A$2:$AB$2, 0))), INDEX($A30:$AB30, MATCH(داشبرد!$D$5, $A$2:$AB$2, 0)), NA()) -> 15
B31: 9 | C31: 10 | D31: 11 | G31: 14 | I31: 7 | J31: 4 | K31: 5 | N31: 5 | P31: 0 | Q31: 2 | R31: 4 | W31: 2 | X31: 4 | Y31: 2 | AB31: 2 | AD31: =IF(ISNUMBER(INDEX($A31:$AB31, MATCH(داشبرد!$D$5, $A$2:$AB$2, 0))), INDEX($A31:$AB31, MATCH(داشبرد!$D$5, $A$2:$AB$2, 0)), NA()) -> 14
B32: 11 | C32: 10 | D32: 9 | G32: 8 | I32: 6 | J32: 4 | K32: 5 | N32: 3 | P32: 2 | Q32: 2 | R32: 2 | W32: 3 | X32: 4 | Y32: 2 | AB32: 2 | AD32: =IF(ISNUMBER(INDEX($A32:$AB32, MATCH(داشبرد!$D$5, $A$2:$AB$2, 0))), INDEX($A32:$AB32, MATCH(داشبرد!$D$5, $A$2:$AB$2, 0)), NA()) -> 8
B33: 11 | C33: 7 | D33: 9 | G33: 7 | I33: 6 | J33: 4 | K33: 5 | N33: 3 | P33: 2 | Q33: 0 | R33: 2 | W33: 3 | X33: 3 | Y33: 2 | AB33: 2 | AD33: =IF(ISNUMBER(INDEX($A33:$AB33, MATCH(داشبرد!$D$5, $A$2:$AB$2, 0))), INDEX($A33:$AB33, MATCH(داشبرد!$D$5, $A$2:$AB$2, 0)), NA()) -> 7
B34: 12 | C34: 7 | D34: 10 | G34: 7 | I34: 6 | J34: 4 | K34: 5 | N34: 3 | P34: 2 | Q34: 0 | R34: 2 | W34: 4 | X34: 3 | Y34: 3 | AB34: 2 | AD34: =IF(ISNUMBER(INDEX($A34:$AB34, MATCH(داشبرد!$D$5, $A$2:$AB$2, 0))), INDEX($A34:$AB34, MATCH(داشبرد!$D$5, $A$2:$AB$2, 0)), NA()) -> 7
B35: 7 | C35: 7 | G35: 9 | I35: 4 | J35: 4 | N35: 3 | P35: 1 | Q35: 0 | W35: 2 | X35: 3 | AB35: 3 | AD35: =IF(ISNUMBER(INDEX($A35:$AB35, MATCH(داشبرد!$D$5, $A$2:$AB$2, 0))), INDEX($A35:$AB35, MATCH(داشبرد!$D$5, $A$2:$AB$2, 0)), NA()) -> 9
B36: 7 | C36: 7 | G36: 9 | I36: 4 | J36: 3 | N36: 3 | P36: 1 | Q36: 2 | W36: 2 | X36: 2 | AB36: 3 | AD36: =IF(ISNUMBER(INDEX($A36:$AB36, MATCH(داشبرد!$D$5, $A$2:$AB$2, 0))), INDEX($A36:$AB36, MATCH(داشبرد!$D$5, $A$2:$AB$2, 0)), NA()) -> 9
B37: 6 | C37: 7 | G37: 10 | I37: 4 | J37: 3 | N37: 3 | P37: 1 | Q37: 2 | W37: 1 | X37: 2 | AB37: 4 | AD37: =IF(ISNUMBER(INDEX($A37:$AB37, MATCH(داشبرد!$D$5, $A$2:$AB$2, 0))), INDEX($A37:$AB37, MATCH(داشبرد!$D$5, $A$2:$AB$2, 0)), NA()) -> 10
B38: 8 | C38: 7 | G38: 11 | I38: 3 | J38: 3 | N38: 8 | P38: 1 | Q38: 2 | W38: 4 | X38: 2 | AB38: 2 | AD38: =IF(ISNUMBER(INDEX($A38:$AB38, MATCH(داشبرد!$D$5, $A$2:$AB$2, 0))), INDEX($A38:$AB38, MATCH(داشبرد!$D$5, $A$2:$AB$2, 0)), NA()) -> 11
B39: 9 | C39: 9 | G39: 12 | I39: 3 | J39: 3 | N39: 8 | P39: 1 | Q39: 2 | W39: 5 | X39: 4 | AB39: 3 | AD39: =IF(ISNUMBER(INDEX($A39:$AB39, MATCH(داشبرد!$D$5, $A$2:$AB$2, 0))), INDEX($A39:$AB39, MATCH(داشبرد!$D$5, $A$2:$AB$2, 0)), NA()) -> 12
C40: 8 | G40: 12 | J40: 3 | N40: 8 | Q40: 1 | X40: 4 | AB40: 3 | AD40: =IF(ISNUMBER(INDEX($A40:$AB40, MATCH(داشبرد!$D$5, $A$2:$AB$2, 0))), INDEX($A40:$AB40, MATCH(داشبرد!$D$5, $A$2:$AB$2, 0)), NA()) -> 12
C41: 9 | G41: 9 | J41: 3 | N41: 4 | Q41: 1 | X41: 5 | AB41: 3 | AD41: =IF(ISNUMBER(INDEX($A41:$AB41, MATCH(داشبرد!$D$5, $A$2:$AB$2, 0))), INDEX($A41:$AB41, MATCH(داشبرد!$D$5, $A$2:$AB$2, 0)), NA()) -> 9
C42: 11 | G42: 9 | J42: 5 | N42: 4 | Q42: 2 | X42: 4 | AB42: 3 | AD42: =IF(ISNUMBER(INDEX($A42:$AB42, MATCH(داشبرد!$D$5, $A$2:$AB$2, 0))), INDEX($A42:$AB42, MATCH(داشبرد!$D$5, $A$2:$AB$2, 0)), NA()) -> 9
...
